Workbook

Sheet Récap
D4: Point anticipations au 04/03/2026
D5: GESTION DES REMBOURSEMENTS (Tombée Échéance du 05/03/2026)
B6: CODE | C6: AGENCE | D6: PREV | E6: REAL | F6: % NBRE | G6: GAP Nbre | H6: PREV | I6: REAL | J6: % VOL | K6: GAP Vol
B7: M100 | C7: BONOUA | D7: ='Listing tombées'!A122 -> 119 | E7: ='Listing tombées'!V122 -> 87 | F7: =E7/D7 -> 0.73109244 | G7: =E7-D7 -> -32 | H7: ='Listing tombées'!J122 -> 13247996 | I7: ='Listing tombées'!S122 -> 10690662 | J7: =I7/H7 -> 0.80696446 | K7: =I7-H7 -> -2557334
B8: M200 | C8: ABOISSO | D8: ='Listing tombées'!A154 -> 31 | E8: ='Listing tombées'!V154 -> 24 | F8: =E8/D8 -> 0.77419355 | G8: =E8-D8 -> -7 | H8: ='Listing tombées'!J154 -> 3415814 | I8: ='Listing tombées'!S154 -> 2956359 | J8: =I8/H8 -> 0.8654918 | K8: =I8-H8 -> -459455
B9: M300 | C9: GRAND-BASSAM | D9: ='Listing tombées'!A308 -> 153 | E9: ='Listing tombées'!V308 -> 81 | F9: =E9/D9 -> 0.52941176 | G9: =E9-D9 -> -72 | H9: ='Listing tombées'!J308 -> 26359627 | I9: ='Listing tombées'!S308 -> 14185773 | J9: =I9/H9 -> 0.53816289 | K9: =I9-H9 -> -12173854
B10: M400 | C10: AGBOVILLE | D10: ='Listing tombées'!A419 -> 110 | E10: ='Listing tombées'!V419 -> 83 | F10: =E10/D10 -> 0.75454545 | G10: =E10-D10 -> -27 | H10: ='Listing tombées'!J419 -> 13053262 | I10: ='Listing tombées'!S419 -> 11081003 | J10: =I10/H10 -> 0.84890681 | K10: =I10-H10 -> -1972259
B11: M500 | C11: TIASSALE | D11: ='Listing tombées'!A559 -> 139 | E11: ='Listing tombées'!V559 -> 97 | F11: =E11/D11 -> 0.69784173 | G11: =E11-D11 -> -42 | H11: ='Listing tombées'!J559 -> 10501270 | I11: ='Listing tombées'!S559 -> 8097605 | J11: =I11/H11 -> 0.77110721 | K11: =I11-H11 -> -2403665
B12: M510 | C12: DIVO | D12: ='Listing tombées'!A599 -> 39 | E12: ='Listing tombées'!V599 -> 25 | F12: =E12/D12 -> 0.64102564 | G12: =E12-D12 -> -14 | H12: ='Listing tombées'!J599 -> 4417040 | I12: ='Listing tombées'!S599 -> 3839586 | J12: =I12/H12 -> 0.86926675 | K12: =I12-H12 -> -577454
B13: M600 | C13: ADZOPE | D13: ='Listing tombées'!A674 -> 74 | E13: ='Listing tombées'!V674 -> 64 | F13: =E13/D13 -> 0.86486486 | G13: =E13-D13 -> -10 | H13: ='Listing tombées'!J674 -> 8838342 | I13: ='Listing tombées'!S674 -> 7890066 | J13: =I13/H13 -> 0.89270884 | K13: =I13-H13 -> -948276
B14: M700 | C14: GRAND-LAHOU | D14: ='Listing tombées'!A724 -> 49 | E14: ='Listing tombées'!V724 -> 38 | F14: =E14/D14 -> 0.7755102 | G14: =E14-D14 -> -11 | H14: ='Listing tombées'!J724 -> 5111652 | I14: ='Listing tombées'!S724 -> 4431544 | J14: =I14/H14 -> 0.86694947 | K14: =I14-H14 -> -680108
B15: M710 | C15: DABOU | D15: ='Listing tombées'!A801 -> 76 | E15: ='Listing tombées'!V801 -> 48 | F15: =E15/D15 -> 0.63157895 | G15: =E15-D15 -> -28 | H15: ='Listing tombées'!J801 -> 12911371 | I15: ='Listing tombées'!S801 -> 10308463 | J15: =I15/H15 -> 0.79840189 | K15: =I15-H15 -> -2602908
B16: TOTAL | D16: =SUM(D7:D15) -> 790 | E16: =SUM(E7:E15) -> 547 | F16: =E16/D16 -> 0.69240506 | G16: =SUM(G7:G15) -> -243 | H16: =SUM(H7:H15) -> 97856374 | I16: =SUM(I7:I15) -> 73481061 | J16: =I16/H16 -> 0.75090725 | K16: =SUM(K7:K15) -> -24375313
C25: AGENCE | D25: % NBRE
C26: BONOUA | D26: 0.73109244
C27: ABOISSO | D27: 0.77419355
C28: GRAND-BASSAM | D28: 0.52941176
C29: AGBOVILLE | D29: 0.75454545
C30: TIASSALE | D30: 0.69784173
C31: DIVO | D31: 0.64102564
C32: ADZOPE | D32: 0.86486486
C33: GRAND-LAHOU | D33: 0.7755102
C34: DABOU | D34: 0.63157895

Sheet Listing tombées
Y1: COMMENTAIRES
A2: N° | B2: Agence | C2: Agent de crédit | D2: Dossier | E2: Code | F2: N° manuel | G2: Client | H2: Produit | I2: Date échéance | J2: Total échéance | K2: Intérêt | L2: Capital | M2: Epargne | N2: Frais de gestion | O2: Commission | P2: Contrat | Q2: Solde | S2: Montant versé | T2: Reste à payer | U2: Statut | V2: Réal Nbre | W2: % Nbre | X2: % Vol | Y2: Montant récupéré | Z2: OBSERVATIONS
A3: 1 | B3: BONOUA | D3: M100PRT2025047U00100 | E3: M10000417 | F3: A00200000417 | G3: N`DAH MANOU 0707938591 | H3: Crédit BFR | I3: 46086 | J3: =SUM(K3:O3) -> 173672 | K3: 34521 | L3: 124993 | M3: 13158 | N3: 0 | O3: 1000 | P3: 11071 | Q3: 315016 | R3: =Q3/J3 -> 1.813856 | S3: =J3 -> 173672 | T3: =S3-J3 -> 0 | U3: OK | V3: 1 | W3: =V3/A3 -> 1 | X3: =S3/J3 -> 1
A4: 1 | B4: BONOUA | D4: M100PRT2025051U00083 | E4: M10000963 | F4: A00200000963 | G4: AMAN SOMALE MARGUERITE 0707178363 | H4: Crédit BFR | I4: 46086 | J4: =SUM(K4:O4) -> 101013 | K4: 8517 | L4: 83163 | M4: 8333 | N4: 0 | O4: 1000 | P4: 10903 | Q4: 215970 | R4: =Q4/J4 -> 2.1380416 | S4: =J4 -> 101013 | T4: =S4-J4 -> 0 | U4: OK | V4: 1 | W4: =V4/A4 -> 1 | X4: =S4/J4 -> 1
A5: 1 | B5: BONOUA | D5: M100PRT2025048U00048 | E5: M10001040 | F5: A00200001040 | G5: ASSOHOUN AYA 0707837244 | H5: Crédit BFR | I5: 46086 | J5: =SUM(K5:O5) -> 70362 | K5: 13281 | L5: 50525 | M5: 5556 | N5: 0 | O5: 1000 | P5: 11058 | Q5: 232294 | R5: =Q5/J5 -> 3.3014127 | S5: =J5 -> 70362 | T5: =S5-J5 -> 0 | U5: OK | V5: 1 | W5: =V5/A5 -> 1 | X5: =S5/J5 -> 1
A6: 1 | B6: BONOUA | D6: M100PRT2025047U00119 | E6: M10001071 | F6: A00200001071 | G6: KONE EPOUSE KONATE ASSETOU 0709189429 | H6: Crédit BFR | I6: 46086 | J6: =SUM(K6:O6) -> 70362 | K6: 20219 | L6: 43587 | M6: 5556 | N6: 0 | O6: 1000 | P6: 11139 | Q6: 94767 | R6: =Q6/J6 -> 1.3468492 | S6: =J6 -> 70362 | T6: =S6-J6 -> 0 | U6: OK | V6: 1 | W6: =V6/A6 -> 1 | X6: =S6/J6 -> 1
A7: 1 | B7: BONOUA | D7: M100PRT2026047U00001 | E7: M10001584 | F7: A00200001584 | G7: ETTIA ANAN LYDIE 0140787680 | H7: Crédit BFR | I7: 46086 | J7: =SUM(K7:O7) -> 139723 | K7: 40438 | L7: 87174 | M7: 11111 | N7: 0 | O7: 1000 | P7: 11138 | Q7: 271205 | R7: =Q7/J7 -> 1.941019 | S7: =J7 -> 139723 | T7: =S7-J7 -> 0 | U7: OK | V7: 1 | W7: =V7/A7 -> 1 | X7: =S7/J7 -> 1
A8: 1 | B8: BONOUA | D8: M100PRT2025047U00101 | E8: M10001610 | F8: A00200001610 | G8: NOGBOU EPOUSE ANIBE AKISSI ELIANE - PELAGIE 0707403728 | H8: Crédit BFR | I8: 46086 | J8: =SUM(K8:O8) -> 105042 | K8: 19963 | L8: 75746 | M8: 8333 | N8: 0 | O8: 1000 | P8: 11081 | Q8: 235403 | R8: =Q8/J8 -> 2.2410369 | S8: =J8 -> 105042 | T8: =S8-J8 -> 0 | U8: OK | V8: 1 | W8: =V8/A8 -> 1 | X8: =S8/J8 -> 1
A9: 1 | B9: BONOUA | D9: M100PRT2025048U00047 | E9: M10001725 | F9: A00200001725 | G9: YAO AFFLA MARIE MADELEINE 0708976741 | H9: Crédit investissement | I9: 46086 | J9: =SUM(K9:O9) -> 100372 | K9: 13808 | L9: 77872 | M9: 7692 | N9: 0 | O9: 1000 | P9: 11082 | Q9: 38765 | R9: =Q9/J9 -> 0.38621329 | S9: =Q9 -> 38765 | T9: =S9-J9 -> -61607 | U9: NOK | W9: =V9/A9 -> 0 | X9: =S9/J9 -> 0.38621329
A10: 1 | B10: BONOUA | D10: M100PRT2025047U00103 | E10: M10001759 | F10: A00200001759 | G10: ELLOH ADJIMAN MADELEINE 0153637707 | H10: Crédit BFR | I10: 46086 | J10: =SUM(K10:O10) -> 150058 | K10: 20712 | L10: 116808 | M10: 11538 | N10: 0 | O10: 1000 | P10: 11096 | Q10: 73022 | R10: =Q10/J10 -> 0.48662517 | S10: =Q10 -> 73022 | T10: =S10-J10 -> -77036 | U10: NOK | W10: =V10/A10 -> 0 | X10: =S10/J10 -> 0.48662517
A11: 1 | B11: BONOUA | D11: M100PRT2025051U00141 | E11: M10002064 | F11: A00200002064 | G11: ADJOBI epouse ADIKOTEKE ABA DANIELLE ESTHER 0757270358 | H11: Crédit BFR | I11: 46086 | J11: =SUM(K11:O11) -> 201027 | K11: 21471 | L11: 161889 | M11: 16667 | N11: 0 | O11: 1000 | P11: 10986 | Q11: 314351 | R11: =Q11/J11 -> 1.5637253 | S11: =J11 -> 201027 | T11: =S11-J11 -> 0 | U11: OK | V11: 1 | W11: =V11/A11 -> 1 | X11: =S11/J11 -> 1
A12: 1 | B12: BONOUA | D12: M100PRT2025049U00088 | E12: M10002216 | F12: A00200002216 | G12: TOUNI TIANA CHANTAL 0747341870 | H12: Crédit BFR | I12: 46086 | J12: =SUM(K12:O12) -> 82611 | K12: 12217 | L12: 62727 | M12: 6667 | N12: 0 | O12: 1000 | P12: 11029 | Q12: 237369 | R12: =Q12/J12 -> 2.8733341 | S12: =J12 -> 82611 | T12: =S12-J12 -> 0 | U12: OK | V12: 1 | W12: =V12/A12 -> 1 | X12: =S12/J12 -> 1
A13: 1 | B13: BONOUA | D13: M100PRT2025048U00001 | E13: M10002408 | F13: A00200002408 | G13: ABA ASSOHOUN MODESTINE LARISSA 0703348303 | H13: Crédit investissement | I13: 46086 | J13: =SUM(K13:O13) -> 278445 | K13: 26449 | L13: 228774 | M13: 22222 | N13: 0 | O13: 1000 | P13: 10681 | Q13: 51232 | R13: =Q13/J13 -> 0.18399325 | S13: =Q13 -> 51232 | T13: =S13-J13 -> -227213 | U13: NOK | W13: =V13/A13 -> 0 | X13: =S13/J13 -> 0.18399325
A14: 1 | B14: BONOUA | D14: M100PRT2025049U00109 | E14: M10002455 | F14: A00200002455 | G14: AYEMOU EPOUSE MOULO BISSIE MODESTINE 0546123869 | H14: Crédit BFR | I14: 46086 | J14: =SUM(K14:O14) -> 101013 | K14: 12883 | L14: 78797 | M14: 8333 | N14: 0 | O14: 1000 | P14: 11108 | Q14: 131133 | R14: =Q14/J14 -> 1.2981794 | S14: =J14 -> 101013 | T14: =S14-J14 -> 0 | U14: OK | V14: 1 | W14: =V14/A14 -> 1 | X14: =S14/J14 -> 1
A15: 1 | B15: BONOUA | D15: M100PRT2025047U00078 | E15: M10002575 | F15: A00200002575 | G15: KOUASSI ESTELLE 0152512140 | H15: Crédit BFR | I15: 46086 | J15: =SUM(K15:O15) -> 101013 | K15: 7353 | L15: 84327 | M15: 8333 | N15: 0 | O15: 1000 | P15: 10872 | Q15: 194173 | R15: =Q15/J15 -> 1.9222575 | S15: =J15 -> 101013 | T15: =S15-J15 -> 0 | U15: OK | V15: 1 | W15: =V15/A15 -> 1 | X15: =S15/J15 -> 1
A16: 1 | B16: BONOUA | D16: M100PRT2026049U00002 | E16: M10002672 | F16: A00200002672 | G16: KOUADIO EPOUSE ELETE AKOUA FIENIN ROSE 0709673206 | H16: Crédit investissement | I16: 46086 | J16: =SUM(K16:O16) -> 51007 | K16: 10356 | L16: 35484 | M16: 4167 | N16: 0 | O16: 1000 | P16: 11135 | Q16: 201378 | R16: =Q16/J16 -> 3.9480463 | S16: =J16 -> 51007 | T16: =S16-J16 -> 0 | U16: OK | V16: 1 | W16: =V16/A16 -> 1 | X16: =S16/J16 -> 1
A17: 1 | B17: BONOUA | D17: M100PRT2025049U00107 | E17: M10002722 | F17: A00200002722 | G17: KRAIDY M`MIN BERTINE 0140784518 | H17: Crédit BFR | I17: 46086 | J17: =SUM(K17:O17) -> 51007 | K17: 6441 | L17: 39399 | M17: 4167 | N17: 0 | O17: 1000 | P17: 11097 | Q17: 231803 | R17: =Q17/J17 -> 4.5445331 | S17: =J17 -> 51007 | T17: =S17-J17 -> 0 | U17: OK | V17: 1 | W17: =V17/A17 -> 1 | X17: =S17/J17 -> 1
A18: 1 | B18: BONOUA | D18: M100PRT2025048U00016 | E18: M10002728 | F18: A00200002728 | G18: KACOU AGATHE 0101311916 | H18: Crédit BFR | I18: 46086 | J18: =SUM(K18:O18) -> 201027 | K18: 14618 | L18: 168742 | M18: 16667 | N18: 0 | O18: 1000 | P18: 10861 | Q18: 118728 | R18: =Q18/J18 -> 0.59060723 | S18: =Q18 -> 118728 | T18: =S18-J18 -> -82299 | U18: NOK | W18: =V18/A18 -> 0 | X18: =S18/J18 -> 0.59060723
A19: 1 | B19: BONOUA | D19: M100PRT2025048U00018 | E19: M10002962 | F19: A00200002962 | G19: NIAMKE ALLOUA DELPHINE 0103188157 | H19: Crédit investissement | I19: 46086 | J19: =SUM(K19:O19) -> 123417 | K19: 13123 | L19: 99294 | M19: 10000 | N19: 0 | O19: 1000 | P19: 10873 | Q19: 116182 | R19: =Q19/J19 -> 0.94137761 | S19: =Q19 -> 116182 | T19: =S19-J19 -> -7235 | U19: NOK | W19: =V19/A19 -> 0 | X19: =S19/J19 -> 0.94137761
A20: 1 | B20: BONOUA | D20: M100PRT2025051U00121 | E20: M10002985 | F20: A00200002985 | G20: AKOI VALOU REGINA MARIE SILVIANNE 0101553217 | H20: Crédit BFR | I20: 46086 | J20: =SUM(K20:O20) -> 105042 | K20: 16857 | L20: 78852 | M20: 8333 | N20: 0 | O20: 1000 | P20: 10958 | Q20: 274160 | R20: =Q20/J20 -> 2.6100036 | S20: =J20 -> 105042 | T20: =S20-J20 -> 0 | U20: OK | V20: 1 | W20: =V20/A20 -> 1 | X20: =S20/J20 -> 1
A21: 1 | B21: BONOUA | D21: M100PRT2025046U00029 | E21: M10003325 | F21: A00200003325 | G21: CISSE AICHA 0757399758 | H21: Crédit BFR | I21: 46086 | J21: =SUM(K21:O21) -> 131017 | K21: 11081 | L21: 108103 | M21: 10833 | N21: 0 | O21: 1000 | P21: 10904 | Q21: 261902 | R21: =Q21/J21 -> 1.9989925 | S21: =J21 -> 131017 | T21: =S21-J21 -> 0 | U21: OK | V21: 1 | W21: =V21/A21 -> 1 | X21: =S21/J21 -> 1
A22: 1 | B22: BONOUA | D22: M100PRT2025048U00053 | E22: M10003345 | F22: A00200003345 | G22: AHOURE ADJOBA HORTENSE 0707080673 | H22: Crédit BFR | I22: 46086 | J22: =SUM(K22:O22) -> 100372 | K22: 13808 | L22: 77872 | M22: 7692 | N22: 0 | O22: 1000 | P22: 11109 | Q22: 135352 | R22: =Q22/J22 -> 1.3485036 | S22: =J22 -> 100372 | T22: =S22-J22 -> 0 | U22: OK | V22: 1 | W22: =V22/A22 -> 1 | X22: =S22/J22 -> 1
A23: 1 | B23: BONOUA | D23: M100PRT2025047U00077 | E23: M10003520 | F23: A00200003520 | G23: ZANMENOU ALIMATOU SADIA 07-57-12-13-20/01-52-41-60-47 | H23: Crédit BFR | I23: 46086 | J23: =SUM(K23:O23) -> 71009 | K23: 5147 | L23: 59029 | M23: 5833 | N23: 0 | O23: 1000 | P23: 10874 | Q23: 12556 | R23: =Q23/J23 -> 0.17682266 | S23: =Q23 -> 12556 | T23: =S23-J23 -> -58453 | U23: NOK | W23: =V23/A23 -> 0 | X23: =S23/J23 -> 0.17682266
A24: 1 | B24: BONOUA | D24: M100PRT2025049U00091 | E24: M10003660 | F24: A00200003660 | G24: FATOUMATA CAMARA 0748131421 | H24: Crédit BFR | I24: 46086 | J24: =SUM(K24:O24) -> 151020 | K24: 17607 | L24: 119913 | M24: 12500 | N24: 0 | O24: 1000 | P24: 11050 | Q24: 448053 | R24: =Q24/J24 -> 2.9668455 | S24: =J24 -> 151020 | T24: =S24-J24 -> 0 | U24: OK | V24: 1 | W24: =V24/A24 -> 1 | X24: =S24/J24 -> 1
A25: 1 | B25: BONOUA | D25: M100PRT2025048U00051 | E25: M10003905 | F25: A00200003905 | G25: KOUAMELAN M`PIKE SABINE 0502477955 | H25: Crédit BFR | I25: 46086 | J25: =SUM(K25:O25) -> 42728 | K25: 8745 | L25: 29825 | M25: 3158 | N25: 0 | O25: 1000 | P25: 11122 | Q25: 79230 | R25: =Q25/J25 -> 1.8542876 | S25: =J25 -> 42728 | T25: =S25-J25 -> 0 | U25: OK | V25: 1 | W25: =V25/A25 -> 1 | X25: =S25/J25 -> 1
A26: 1 | B26: BONOUA | D26: M100PRT2025049U00079 | E26: M10004052 | F26: A00200004052 | G26: MITOKPE SEDOMON NADEGE PULCHERIE 0143114710 | H26: Crédit BFR | I26: 46086 | J26: =SUM(K26:O26) -> 201027 | K26: 21359 | L26: 162001 | M26: 16667 | N26: 0 | O26: 1000 | P26: 10991 | Q26: 342613 | R26: =Q26/J26 -> 1.7043134 | S26: =J26 -> 201027 | T26: =S26-J26 -> 0 | U26: OK | V26: 1 | W26: =V26/A26 -> 1 | X26: =S26/J26 -> 1
A27: 1 | B27: BONOUA | D27: M100PRT2025048U00044 | E27: M10004151 | F27: A00200004151 | G27: FOFANA AICHA 0140221266 | H27: Crédit BFR | I27: 46086 | J27: =SUM(K27:O27) -> 71009 | K27: 9047 | L27: 55129 | M27: 5833 | N27: 0 | O27: 1000 | P27: 11084 | Q27: 37574 | R27: =Q27/J27 -> 0.52914419 | S27: =Q27 -> 37574 | T27: =S27-J27 -> -33435 | U27: NOK | W27: =V27/A27 -> 0 | X27: =S27/J27 -> 0.52914419
A28: 1 | B28: BONOUA | D28: M100PRT2025049U00111 | E28: M10004301 | F28: A00200004301 | G28: KANTE FANTA 0506516512 | H28: Crédit BFR | I28: 46086 | J28: =SUM(K28:O28) -> 31004 | K28: 6214 | L28: 21290 | M28: 2500 | N28: 0 | O28: 1000 | P28: 11134 | Q28: 37724 | R28: =Q28/J28 -> 1.2167462 | S28: =J28 -> 31004 | T28: =S28-J28 -> 0 | U28: OK | V28: 1 | W28: =V28/A28 -> 1 | X28: =S28/J28 -> 1
A29: 1 | B29: BONOUA | D29: M100PRT2025049U00112 | E29: M10004306 | F29: A00200004306 | G29: DIARRA SETOU 0555308997 | H29: Crédit BFR | I29: 46086 | J29: =SUM(K29:O29) -> 31004 | K29: 6214 | L29: 21290 | M29: 2500 | N29: 0 | O29: 1000 | P29: 11136 | Q29: 46571 | R29: =Q29/J29 -> 1.5020965 | S29: =J29 -> 31004 | T29: =S29-J29 -> 0 | U29: OK | V29: 1 | W29: =V29/A29 -> 1 | X29: =S29/J29 -> 1
A30: 1 | B30: BONOUA | D30: M100PRT2025046U00042 | E30: M10004414 | F30: A00200004414 | G30: OBROU LARISSA ESTELLE 0749935475 | H30: Crédit BFR | I30: 46086 | J30: =SUM(K30:O30) -> 151020 | K30: 17638 | L30: 119882 | M30: 12500 | N30: 0 | O30: 1000 | P30: 11033 | Q30: 242215 | R30: =Q30/J30 -> 1.6038604 | S30: =J30 -> 151020 | T30: =S30-J30 -> 0 | U30: OK | V30: 1 | W30: =V30/A30 -> 1 | X30: =S30/J30 -> 1
A31: 1 | B31: BONOUA | D31: M100PRT2025048U00042 | E31: M10004618 | F31: A00200004618 | G31: KANGAH ATTOUOH LAURA YVANA 07-67-11-73-79/01-43-18-40-19 | H31: Crédit BFR | I31: 46086 | J31: =SUM(K31:O31) -> 105042 | K31: 19973 | L31: 75736 | M31: 8333 | N31: 0 | O31: 1000 | P31: 11066 | Q31: 202037 | R31: =Q31/J31 -> 1.9233925 | S31: =J31 -> 105042 | T31: =S31-J31 -> 0 | U31: OK | V31: 1 | W31: =V31/A31 -> 1 | X31: =S31/J31 -> 1
A32: 1 | B32: BONOUA | D32: M100PRT2025049U00113 | E32: M10004769 | F32: A00200004769 | G32: DIARRA AMINATA 0748277299 | H32: Crédit BFR | I32: 46086 | J32: =SUM(K32:O32) -> 71009 | K32: 14499 | L32: 49677 | M32: 5833 | N32: 0 | O32: 1000 | P32: 11137 | Q32: 21876 | R32: =Q32/J32 -> 0.30807362 | S32: =Q32 -> 21876 | T32: =S32-J32 -> -49133 | U32: NOK | W32: =V32/A32 -> 0 | X32: =S32/J32 -> 0.30807362
A33: 1 | B33: BONOUA | D33: M100PRT2025048U00012 | E33: M10004813 | F33: A00200004813 | G33: KADJO MANGUE ELISABETH 0777797121 | H33: Crédit BFR | I33: 46086 | J33: =SUM(K33:O33) -> 251033 | K33: 15241 | L33: 213959 | M33: 20833 | N33: 0 | O33: 1000 | P33: 10849 | Q33: 22784 | R33: =Q33/J33 -> 0.090760976 | S33: =Q33 -> 22784 | T33: =S33-J33 -> -228249 | U33: NOK | W33: =V33/A33 -> 0 | X33: =S33/J33 -> 0.090760976
A34: 1 | B34: BONOUA | D34: M100PRT2025047U00087 | E34: M10004826 | F34: A00200004826 | G34: SORO FOUNZOGORY 0173718140 | H34: Crédit BFR | I34: 46086 | J34: =SUM(K34:O34) -> 71009 | K34: 5091 | L34: 59085 | M34: 5833 | N34: 0 | O34: 1000 | P34: 10890 | Q34: 128497 | R34: =Q34/J34 -> 1.8095875 | S34: =J34 -> 71009 | T34: =S34-J34 -> 0 | U34: OK | V34: 1 | W34: =V34/A34 -> 1 | X34: =S34/J34 -> 1
A35: 1 | B35: BONOUA | D35: M100PRT2025051U00085 | E35: M10004895 | F35: A00200004895 | G35: BOSSON épouse KOUAME AHISSIA MARIE 0707584780 | H35: Crédit BFR | I35: 46086 | J35: =SUM(K35:O35) -> 51007 | K35: 4258 | L35: 41582 | M35: 4167 | N35: 0 | O35: 1000 | P35: 10906 | Q35: 291851 | R35: =Q35/J35 -> 5.7217833 | S35: =J35 -> 51007 | T35: =S35-J35 -> 0 | U35: OK | V35: 1 | W35: =V35/A35 -> 1 | X35: =S35/J35 -> 1
A36: 1 | B36: BONOUA | D36: M100PRT2025049U00106 | E36: M10005035 | F36: A00200005035 | G36: KONE BEZOU MARIE ROLANDE 0747639001 | H36: Crédit BFR | I36: 46086 | J36: =SUM(K36:O36) -> 51007 | K36: 6441 | L36: 39399 | M36: 4167 | N36: 0 | O36: 1000 | P36: 11110 | Q36: 24124 | R36: =Q36/J36 -> 0.47295469 | S36: =Q36 -> 24124 | T36: =S36-J36 -> -26883 | U36: NOK | W36: =V36/A36 -> 0 | X36: =S36/J36 -> 0.47295469
A37: 1 | B37: BONOUA | D37: M100PRT2025051U00148 | E37: M10005054 | F37: A00200005054 | G37: ELLOH épouse NOGBOU AMON GENEVIEVE 0103515147 | H37: Crédit investissement | I37: 46086 | J37: =SUM(K37:O37) -> 51007 | K37: 5876 | L37: 39964 | M37: 4167 | N37: 0 | O37: 1000 | P37: 11034 | Q37: 118530 | R37: =Q37/J37 -> 2.3237987 | S37: =J37 -> 51007 | T37: =S37-J37 -> 0 | U37: OK | V37: 1 | W37: =V37/A37 -> 1 | X37: =S37/J37 -> 1
A38: 1 | B38: BONOUA | D38: M100PRT2025048U00015 | E38: M10005069 | F38: A00200005069 | G38: ATTOUMOU AFFLA MARIE DIANA 0747595321 | H38: Crédit BFR | I38: 46086 | J38: =SUM(K38:O38) -> 501067 | K38: 36618 | L38: 421782 | M38: 41667 | N38: 0 | O38: 1000 | P38: 10875 | Q38: 0 | R38: =Q38/J38 -> 0 | S38: =Q38 -> 0 | T38: =S38-J38 -> -501067 | U38: NOK | W38: =V38/A38 -> 0 | X38: =S38/J38 -> 0
A39: 1 | B39: BONOUA | D39: M100PRT2025046U00061 | E39: M10005147 | F39: A00200005147 | G39: ADJA ADJOBA ISABELLE 0505794026 | H39: Crédit BFR | I39: 46086 | J39: =SUM(K39:O39) -> 20874 | K39: 2762 | L39: 15574 | M39: 1538 | N39: 0 | O39: 1000 | P39: 11100 | Q39: 68891 | R39: =Q39/J39 -> 3.3003258 | S39: =J39 -> 20874 | T39: =S39-J39 -> 0 | U39: OK | V39: 1 | W39: =V39/A39 -> 1 | X39: =S39/J39 -> 1
A40: 1 | B40: BONOUA | D40: M100PRT2025046U00063 | E40: M10005199 | F40: A00200005199 | G40: ADJOBI ADJOBA FLORENCE ESTELLE 0757419822 | H40: Crédit BFR | I40: 46086 | J40: =SUM(K40:O40) -> 199745 | K40: 27616 | L40: 155744 | M40: 15385 | N40: 0 | O40: 1000 | P40: 11101 | Q40: 471393 | R40: =Q40/J40 -> 2.359974 | S40: =J40 -> 199745 | T40: =S40-J40 -> 0 | U40: OK | V40: 1 | W40: =V40/A40 -> 1 | X40: =S40/J40 -> 1
...
